<?xml version='1.0' encoding='UTF-8'?>
<robot name="pendulum">
  <link name="base">
    <inertial>
      <origin xyz="0.0 0.0 0.0" rpy="0.0 -0.0 0.0"/>
      <mass value="1.0"/>
      <inertia ixx="1.0" ixy="0.0" ixz="0.0" iyy="1.0" iyz="0.0" izz="1.0"/>
    </inertial>
  </link>
  <link name="top">
    <inertial>
      <origin xyz="0.0 0.0 0.0" rpy="0.0 0.0 0.0"/>
      <mass value="5000.0"/>
      <inertia ixx="0.1" ixy="0.0" ixz="0.0" iyy="0.1" iyz="0.0" izz="0.1"/>
    </inertial>
    <visual>
      <geometry>
        <box size="0.01 0.01 0.01"/>
      </geometry>
      <origin xyz="0.0 0.0 0.0" rpy="0.0 0.0 0.0"/>
    </visual>
    <collision>
      <geometry>
        <box size="0.01 0.01 0.01"/>
      </geometry>
      <origin xyz="0.0 0.0 0.0" rpy="0.0 0.0 0.0"/>
    </collision>
  </link>
  <link name="rod">
    <inertial>
      <origin xyz="0.0 0.0 -0.15" rpy="0.0 0.0 0.0"/>
      <mass value="0.01"/>
      <inertia ixx="0.1" ixy="0.0" ixz="0.0" iyy="0.1" iyz="0.0" izz="0.1"/>
    </inertial>
    <visual>
      <geometry>
        <cylinder radius="0.005" length="0.3"/>
      </geometry>
      <material name="Grey"/>
      <origin xyz="0.0 0.0 -0.15" rpy="0.0 0.0 0.0"/>
    </visual>
    <collision>
      <geometry>
        <cylinder radius="0.005" length="0.3"/>
      </geometry>
      <origin xyz="0.0 0.0 -0.15" rpy="0.0 0.0 0.0"/>
    </collision>
  </link>
  <link name="box">
    <inertial>
      <origin xyz="0.0 0.0 0.0" rpy="0.0 0.0 0.0"/>
      <mass value="1000.0"/>
      <inertia ixx="0.001" ixy="0.0" ixz="0.0" iyy="0.001" iyz="0.0" izz="0.001"/>
    </inertial>
    <visual>
      <geometry>
        <box size="0.03 0.03 0.03"/>
      </geometry>
      <material name="Blue"/>
      <origin xyz="0.0 0.0 0.0" rpy="0.0 0.0 0.0"/>
    </visual>
    <collision>
      <geometry>
        <box size="0.03 0.03 0.03"/>
      </geometry>
      <origin xyz="0.0 0.0 0.0" rpy="0.0 0.0 0.0"/>
    </collision>
  </link>
  <joint name="joint" type="continuous">
    <parent link="base"/>
    <child link="top"/>
    <axis xyz="0. 0. 1."/>
    <origin xyz="0.0 0.0 0.33" rpy="0.0 0.0 0.0"/>
  </joint>
  <joint name="pendulum_joint" type="continuous">
    <parent link="top"/>
    <child link="rod"/>
    <axis xyz="1. 0. 0."/>
    <origin xyz="0.0 0.0 0.0" rpy="0.0 0.0 0.0"/>
  </joint>
  <joint name="ball_joint" type="fixed">
    <parent link="rod"/>
    <child link="box"/>
    <axis xyz="1. 0. 0."/>
    <origin xyz="0.0 0.0 -0.3" rpy="0.0 0.0 0.0"/>
  </joint>
  <material name="Blue">
    <color rgba="0. 0. 1. 1."/>
  </material>
  <material name="Grey">
    <color rgba="0.5 0.5 0.5 1. "/>
  </material>
</robot>
